0.21.0+cpu

    _|    _|  _|    _|    _|_|_|    _|_|_|  _|_|_|  _|      _|    _|_|_|      _|_|_|_|    _|_|      _|_|_|  _|_|_|_|
    _|    _|  _|    _|  _|        _|          _|    _|_|    _|  _|            _|        _|    _|  _|        _|
    _|_|_|_|  _|    _|  _|  _|_|  _|  _|_|    _|    _|  _|  _|  _|  _|_|      _|_|_|    _|_|_|_|  _|        _|_|_|
    _|    _|  _|    _|  _|    _|  _|    _|    _|    _|    _|_|  _|    _|      _|        _|    _|  _|        _|
    _|    _|    _|_|      _|_|_|    _|_|_|  _|_|_|  _|      _|    _|_|_|      _|        _|    _|    _|_|_|  _|_|_|_|
Traceback (most recent call last):
  File "C:\Users\aynaz\miniconda3\Lib\site-packages\huggingface_hub\utils\_http.py", line 409, in hf_raise_for_status
    response.raise_for_status()
  File "C:\Users\aynaz\miniconda3\Lib\site-packages\requests\models.py", line 1024, in raise_for_status
    raise HTTPError(http_error_msg, response=self)
requests.exceptions.HTTPError: 401 Client Error: Unauthorized for url: https://huggingface.co/api/whoami-v2

The above exception was the direct cause of the following exception:

Traceback (most recent call last):
  File "C:\Users\aynaz\miniconda3\Lib\site-packages\huggingface_hub\hf_api.py", line 1664, in whoami
    hf_raise_for_status(r)
  File "C:\Users\aynaz\miniconda3\Lib\site-packages\huggingface_hub\utils\_http.py", line 481, in hf_raise_for_status
    raise _format(HfHubHTTPError, str(e), response) from e
huggingface_hub.errors.HfHubHTTPError: 401 Client Error: Unauthorized for url: https://huggingface.co/api/whoami-v2 (Request ID: Root=1-67e10f5d-7a367b9145313a51207d8759;b3a3603b-0050-40a1-b687-738c7ec63140)

Invalid credentials in Authorization header

The above exception was the direct cause of the following exception:

Traceback (most recent call last):
  File "D:\Uncertainity Analysis-Ferhat\week5\titan.py", line 36, in <module>
    login()
  File "C:\Users\aynaz\miniconda3\Lib\site-packages\huggingface_hub\utils\_deprecation.py", line 101, in inner_f
    return f(*args, **kwargs)
           ^^^^^^^^^^^^^^^^^^
  File "C:\Users\aynaz\miniconda3\Lib\site-packages\huggingface_hub\utils\_deprecation.py", line 31, in inner_f
    return f(*args, **kwargs)
           ^^^^^^^^^^^^^^^^^^
  File "C:\Users\aynaz\miniconda3\Lib\site-packages\huggingface_hub\_login.py", line 130, in login
    interpreter_login(new_session=new_session)
  File "C:\Users\aynaz\miniconda3\Lib\site-packages\huggingface_hub\utils\_deprecation.py", line 101, in inner_f
    return f(*args, **kwargs)
           ^^^^^^^^^^^^^^^^^^
  File "C:\Users\aynaz\miniconda3\Lib\site-packages\huggingface_hub\utils\_deprecation.py", line 31, in inner_f
    return f(*args, **kwargs)
           ^^^^^^^^^^^^^^^^^^
  File "C:\Users\aynaz\miniconda3\Lib\site-packages\huggingface_hub\_login.py", line 290, in interpreter_login
    _login(token=token, add_to_git_credential=add_to_git_credential)
  File "C:\Users\aynaz\miniconda3\Lib\site-packages\huggingface_hub\_login.py", line 404, in _login
    token_info = whoami(token)
                 ^^^^^^^^^^^^^
  File "C:\Users\aynaz\miniconda3\Lib\site-packages\huggingface_hub\utils\_validators.py", line 114, in _inner_fn
    return fn(*args, **kwargs)
           ^^^^^^^^^^^^^^^^^^^
  File "C:\Users\aynaz\miniconda3\Lib\site-packages\huggingface_hub\hf_api.py", line 1677, in whoami
    raise HTTPError(error_message, request=e.request, response=e.response) from e
requests.exceptions.HTTPError: Invalid user token.

[0m
